<robot name= "myFirst">
	<link name="base_link">
		<visual>
			<geometry>
				<cylinder length="0.1" radius="0.2"/>
			</geometry>
			<origin xyz="0 0 0.05" rpy="0 0 0"/>
		</visual>	
	</link>
	<link name="link_1">
		<visual>
			<geometry>
				<box size="0.2 0.1 0.1"/>	
			</geometry>
			<origin xyz="0 0 0.05" rpy="0 0 0"/>
			<material name="blue">
        		<color rgba="0 0 .8 1"/>
      		</material>
		</visual>
		
	</link>

	<link name="link_2">
		<visual>
			<geometry>
				<cylinder length="0.3" radius="0.025"/>	
			</geometry>
			<origin xyz="0 -0.15 0" rpy="1.57 0 0"/>
			<material name="yellow">
        		<color rgba="1 1 0 1"/>
      		</material>
		</visual>
	</link>

	<link name="link_3">
		<visual>
			<geometry>
				<cylinder length="0.05" radius="0.025"/>	
			</geometry>
			<origin xyz="0 0 0" rpy="0 0 0"/>
			<material name="white">
        		<color rgba="1 1 1 1"/>
      		</material>
		</visual>
	</link>

	<link name="link_4">
		<visual>
			<geometry>
				<cylinder length="0.3" radius="0.025"/>	
			</geometry>
			<origin xyz="0 0 -0.15" rpy="0 0 0"/>
			<material name="yellow"/>
		</visual>
	</link>

	<link name="link_5">
		<visual>
			<geometry>
				<cylinder length="0.05" radius="0.025"/>	
			</geometry>
			<origin xyz="0 0 0" rpy="0 0 0"/>
			<material name="white"/>
		</visual>
	</link>

	<link name="link_6">
		<visual>
			<geometry>
				<cylinder length="0.1" radius="0.025"/>	
			</geometry>
			<origin xyz="0 0 -0.05" rpy="0 0 0"/>
			<material name="yellow"/>
		</visual>
	</link>


	<joint name="joint_0" type="fixed">
		<parent link="base_link"/>
		<child link="link_1"/>
		<origin xyz="0 0 0.1" rpy="0 0 0"/>
	</joint>
	<joint name="joint_1" type="revolute">
		<parent link="base_link"/>
		<child link="link_1"/>
		<limit effort="100" velocity="180" lower="-3.14" upper="3.14"/>
		<origin xyz="0 0 0.1" rpy="0 0 0"/>
		<axis xyz="0 0 1"/>
	</joint>
	<joint name="joint_2" type="revolute">
		<parent link="link_1"/>
		<child link="link_2"/>
		<limit effort="100" velocity="180" lower="-3.14" upper="3.14"/>
		<origin xyz="0.1 0 0" rpy="-1.57 0 0"/>
		<axis xyz="0 0 1"/>
	</joint>

	<joint name="joint_3" type="revolute">
		<parent link="link_2"/>
		<child link="link_3"/>
		<limit effort="100" velocity="180" lower="-3.14" upper="3.14"/>
		<origin xyz="0 -0.3 0" rpy="3.14 0 -1.57"/>
		<axis xyz="0 0 1"/>
	</joint>

	<joint name="joint_4" type="revolute">
		<parent link="link_3"/>
		<child link="link_4"/>
		<limit effort="100" velocity="180" lower="-3.14" upper="3.14"/>
		<origin xyz="0.02 0 0" rpy="-1.57 0 0"/>
		<axis xyz="0 0 1"/>
	</joint>

	<joint name="joint_5" type="revolute">
		<parent link="link_4"/>
		<child link="link_5"/>
		<limit effort="100" velocity="180" lower="-3.14" upper="3.14"/>
		<origin xyz="0 0 -0.3" rpy="1.57 0 0"/>
		<axis xyz="0 0 1"/>
	</joint>
	<joint name="joint_6" type="revolute">
		<parent link="link_5"/>
		<child link="link_6"/>
		<limit effort="100" velocity="180" lower="-3.14" upper="3.14"/>
		<origin xyz="0 -0.1 0" rpy="1.57 0 0"/>
		<axis xyz="0 0 1"/>
	</joint>
	
</robot>
